Workbook

Sheet Frontend
A1: Quantifizierung von Lärmschadenskosten
A4: Methodik
A5: Engelmann, N., Blanes Guàrdia, N., Fons-Esteve, J., Vienneau, D., Peris, E., & Röösli, M. (2025). Environmental noise health risk assessment: Methodology for assessing health risks using data reported under the Environmental Noise Directive (ETC HE Report 2023/11: Version 3). Eionet Portal. https://doi.org/10.5281/zenodo.15641306
A8: Eingabe
A10: Anzahl belasteter Personen nach ULR (EN: END)
C12: Lden | J12: Lnight
C13: Exposed Lden5559 | D13: Exposed Lden6064 | E13: Exposed Lden6569 | F13: Exposed Lden7074 | G13: Exposed Lden75 | H13: Summe | J13: Exposed Lnight5054 | K13: Exposed Lnight5559 | L13: Exposed Lnight6064 | M13: Exposed Lnight6569 | N13: Exposed Lnight70 | O13: Summe
A14: road | B14: mroad outAgg | C14: 3725500 | D14: 1643600 | E14: 998600 | F14: 481900 | G14: 33500 | H14: =SUM(C14:G14) -> 6883100 | J14: 2411700 | K14: 1244300 | L14: 574000 | M14: 54400 | N14: 2100 | O14: =SUM(J14:N14) -> 4286500
B15: Agglomeration road (aggroad) | C15: 3762100 | D15: 3050900 | E15: 2479000 | F15: 1006400 | G15: 99800 | H15: =SUM(C15:G15) -> 10398200 | J15: 3383500 | K15: 2682400 | L15: 1283500 | M15: 156200 | N15: 4900 | O15: =SUM(J15:N15) -> 7510500
A18: rail | B18: mrail outAgg | C18: 716500 | D18: 340700 | E18: 141700 | F18: 36000 | G18: 4600 | H18: =SUM(C18:G18) -> 1239500 | J18: 568900 | K18: 258600 | L18: 93100 | M18: 21100 | N18: 2200 | O18: =SUM(J18:N18) -> 943900
B19: aggrail | C19: 1289300 | D19: 787600 | E19: 383200 | F19: 74300 | G19: 13200 | H19: =SUM(C19:G19) -> 2547600 | J19: 1058400 | K19: 609100 | L19: 175500 | M19: 32000 | N19: 7700 | O19: =SUM(J19:N19) -> 1882700
A22: air | B22: mair outAgg | C22: 303900 | D22: 69900 | E22: 3900 | F22: 0 | G22: 0 | H22: =SUM(C22:G22) -> 377700 | J22: 123200 | K22: 17600 | L22: 400 | M22: 0 | N22: 0 | O22: =SUM(J22:N22) -> 141200
B23: aggair | C23: 419800 | D23: 51900 | E23: 3000 | F23: 700 | G23: 0 | H23: =SUM(C23:G23) -> 475400 | J23: 121500 | K23: 10900 | L23: 400 | M23: 0 | N23: 0 | O23: =SUM(J23:N23) -> 132800
A30: Ausgabe
A32: Agglomeration road
C34: Anzahl belasteter Personen ab 25 dB
B35: Lden | C35: ='Agglomeration road'!C18 -> 20796421
B36: Lnight | C36: ='Agglomeration road'!C19 -> 15021000

Sheet Agglomeration road
A1: Agglomeration road
A4: Assessment of noise exposure below the END thresholds
A6: relative fractions DE to calculate the exposure values below the END thresholds at 5 dB for L_den and L_night road noise inside agglomerations
C7: Fraction 25 - 29 dB | D7: Fraction 30 - 34 dB | E7: Fraction 35 - 39 dB | F7: Fraction 40 - 44 dB | G7: Fraction 45 - 49 dB | H7: Fraction 50 - 54 dB
B8: Lden | C8: 0.001425 | D8: 0.00417 | E8: 0.016857 | F8: 0.068123 | G8: 0.278499 | H8: 0.630928
B9: Lnight | C9: 0.008599 | D9: 0.031837 | E9: 0.149939 | F9: 0.377951 | G9: 0.431674 | H9: -
A11: estimate the number of people exposed below the END thresholds for road noise inside agglomerations
C12: Exposed 25 - 29 dB | D12: Exposed 30 - 34 dB | E12: Exposed 35 - 39 dB | F12: Exposed 40 - 44 dB | G12: Exposed 45 - 49 dB | H12: Exposed 50 - 54 dB | I12: Sum Lden < 55 dB Lnight < 50 dB
B13: Lden | C13: =Frontend!$H$15*C8 -> 14817.435 | D13: =Frontend!$H$15*D8 -> 43360.494 | E13: =Frontend!$H$15*E8 -> 175282.46 | F13: =Frontend!$H$15*F8 -> 708356.58 | G13: =Frontend!$H$15*G8 -> 2895888.3 | H13: =Frontend!$H$15*H8 -> 6560515.5 | I13: =SUM(C13:H13) -> 10398221
B14: Lnight | C14: =Frontend!$O$15*C9 -> 64582.79 | D14: =Frontend!$O$15*D9 -> 239111.79 | E14: =Frontend!$O$15*E9 -> 1126116.9 | F14: =Frontend!$O$15*F9 -> 2838601 | G14: =Frontend!$O$15*G9 -> 3242087.6 | H14: - | I14: =SUM(C14:G14) -> 7510500
A16: summarize the number of people exposed below adn above the END thresholds for road noise inside agglomerations
C17: Sum of people exposed
B18: Lden | C18: =Frontend!$H$15+I13 -> 20796421
B19: Lnight | C19: =Frontend!$O$15+I14 -> 15021000
A22: Methodology to improve the transfer process from 5 dB to 1 dB exposure distribution (OFFEN)
B24: tbc
A27: ERF
B29: outcome | C29: risk_type | D29: outcome_type | E29: population_type | F29: source | G29: ERF | H29: metric | I29: threshold in dB | J29: DW | K29: END_model | L29: EEA_model | M29: reference
B30: High noise annoyance (HA) | C30: absolute_risk | D30: prevalence | E30: adults | F30: road | G30: 78.9270 - 3.1162 * c + 0.0342 * c^2 | H30: lden | I30: 45 | J30: 0.011 | K30: 1 | L30: 1 | M30: Guski et al. (2017)
B31: High sleep disturbance (HSD) | C31: absolute_risk | D31: prevalence | E31: adults | F31: road | G31: 19.4312 - 0.9336 * c + 0.0126 * c^2 | H31: lnight | I31: 40 | J31: 0.01 | K31: 1 | L31: 1 | M31: Basner and McGuire (2018)
B32: All-cause mortality | C32: relative_risk | D32: incidence | E32: adults | F32: road | G32: ifelse(c>threshold,(c-threshold)*1.055,0) | H32: lden | I32: 45 | K32: 0 | L32: 1 | M32: Engelmann et al. (2025), ch. 3.3.1
B33: Cardiovascular disease (CVD) | C33: relative_risk | D33: incidence | E33: adults | F33: road | G33: ifelse(c>threshold,(c-threshold)*1.032,0) | H33: lden | I33: 45 | K33: 0 | L33: 1 | M33: Engelmann et al. (2025), ch. 3.3.2
B34: Diabetes | C34: relative_risk | D34: incidence | E34: adults | F34: road | G34: ifelse(c>threshold,(c-threshold)*1.062,0) | H34: lden | I34: 45 | K34: 0 | L34: 1 | M34: Engelmann et al. (2025), ch. 3.3.3
B35: Ischaemic Heart Disease (IHD) | C35: relative_risk | D35: incidence | E35: adults | F35: road | G35: ifelse(c>threshold, e^((ln(1,08)/10)*(c-threshold)), 1) | H35: lden | I35: 53 | K35: 1 | L35: 0 | M35: END Annex III
A38: Calculation of YLL and YLD
D40: estimated number of people exposed below the END threshold (Lden < 55 dB(A)) | J40: number of people exposed according to END (Lden >= 55 dB(A))
D41: Sum | E41: Exposed 25 - 29 dB | F41: Exposed 30 - 34 dB | G41: Exposed 35 - 39 dB | H41: Exposed 40 - 44 dB | I41: Exposed 45 - 49 dB | J41: Exposed 50 - 54 dB | K41: Exposed Lden5559 | L41: Exposed Lden6064 | M41: Exposed Lden6569 | N41: Exposed Lden7074 | O41: Exposed Lden75
A42: General | B42: aggroad number exposed | D42: =SUM(E42:O42) -> 20796421 | E42: =C13 -> 14817.435 | F42: =D13 -> 43360.494 | G42: =E13 -> 175282.46 | H42: =F13 -> 708356.58 | I42: =G13 -> 2895888.3 | J42: =H13 -> 6560515.5 | K42: =Frontend!C15 -> 3762100 | L42: =Frontend!D15 -> 3050900 | M42: =Frontend!E15 -> 2479000 | N42: =Frontend!F15 -> 1006400 | O42: =Frontend!G15 -> 99800
B43: M[Ni] = midpoint of noise exposure in each category in dB | E43: 27 | F43: 32 | G43: 37 | H43: 42 | I43: 47 | J43: 52 | K43: 57 | L43: 62 | M43: 67 | N43: 72 | O43: 77
B44: p[i] = proportion of the population in each noise exposure category Ni | E44: =E42/$D$42 -> 0.00071249929 | F44: =F42/$D$42 -> 0.0020849979 | G44: =G42/$D$42 -> 0.0084284916 | H44: =H42/$D$42 -> 0.034061466 | I44: =I42/$D$42 -> 0.13924936 | J44: =J42/$D$42 -> 0.31546368 | K44: =K42/$D$42 -> 0.18090132 | L44: =L42/$D$42 -> 0.14670313 | ... O44: =O42/$D$42 -> 0.0047989027
A45: Model | C45: END model | D45: EEA model
A46: All-cause mortality | B46: RR[Ni] = relative risk for each noise exposure category | E46: =IF(E43>$I$32, EXP((LN(1.055)/10)*(E43-$I$32)),1) -> 1 | F46: =IF(F43>$I$32, EXP((LN(1.055)/10)*(F43-$I$32)),1) -> 1 | G46: =IF(G43>$I$32, EXP((LN(1.055)/10)*(G43-$I$32)),1) -> 1 | H46: =IF(H43>$I$32, EXP((LN(1.055)/10)*(H43-$I$32)),1) -> 1 | I46: =IF(I43>$I$32, EXP((LN(1.055)/10)*(I43-$I$32)),1) -> 1.0107657 | J46: =IF(J43>$I$32, EXP((LN(1.055)/10)*(J43-$I$32)),1) -> 1.0381897 | K46: =IF(K43>$I$32, EXP((LN(1.055)/10)*(K43-$I$32)),1) -> 1.0663578 | L46: =IF(L43>$I$32, EXP((LN(1.055)/10)*(L43-$I$32)),1) -> 1.0952901 | ... O46: =IF(O43>$I$32, EXP((LN(1.055)/10)*(O43-$I$32)),1) -> 1.1868829
B47: Sum pi * (RR[Ni]-1) | C47: =SUM(K47:O47) -> 0.049308311 | D47: =SUM(E47:O47) -> 0.062854894 | E47: =E44*(E46-1) -> 0 | F47: =F44*(F46-1) -> 0 | G47: =G44*(G46-1) -> 0 | H47: =H44*(H46-1) -> 0 | I47: =I44*(I46-1) -> 0.0014991156 | J47: =J44*(J46-1) -> 0.012047468 | K47: =K44*(K46-1) -> 0.012004214 | L47: =L44*(L46-1) -> 0.013979363 | ... O47: =O44*(O46-1) -> 0.00089683283
B48: AFtot = Total attributable fraction from noise exposure | C48: =(C47)/(1+C47) -> 0.046991251 | D48: =(D47)/(1+D47) -> 0.059137794
B49: YLL = YLLnat (= 0,2069215) ∙ AFtot | C49: =0.2069215*C48 -> 0.0097235002 | D49: =0.2069215*D48 -> 0.012236881
A50: Cardiovascular disease | B50: RR[Ni] = relative risk for each noise exposure category | E50: =IF(E43>$I$33, EXP((LN(1.032)/10)*(E43-$I$33)),1) -> 1 | F50: =IF(F43>$I$33, EXP((LN(1.032)/10)*(F43-$I$33)),1) -> 1 | G50: =IF(G43>$I$33, EXP((LN(1.032)/10)*(G43-$I$33)),1) -> 1 | H50: =IF(H43>$I$33, EXP((LN(1.032)/10)*(H43-$I$33)),1) -> 1 | I50: =IF(I43>$I$33, EXP((LN(1.032)/10)*(I43-$I$33)),1) -> 1.0063196 | J50: =IF(J43>$I$33, EXP((LN(1.032)/10)*(J43-$I$33)),1) -> 1.0222939 | K50: =IF(K43>$I$33, EXP((LN(1.032)/10)*(K43-$I$33)),1) -> 1.0385218 | L50: =IF(L43>$I$33, EXP((LN(1.032)/10)*(L43-$I$33)),1) -> 1.0550074 | ... O50: =IF(O43>$I$33, EXP((LN(1.032)/10)*(O43-$I$33)),1) -> 1.1060507
B51: Sum pi * (RR[Ni]-1) | C51: =SUM(K51:O51) -> 0.028396427 | D51: =SUM(E51:O51) -> 0.036309359 | E51: =E44*(E50-1) -> 0 | F51: =F44*(F50-1) -> 0 | G51: =G44*(G50-1) -> 0 | H51: =H44*(H50-1) -> 0 | I51: =I44*(I50-1) -> 0.00088000283 | J51: =J44*(J50-1) -> 0.0070329297 | K51: =K44*(K50-1) -> 0.0069686529 | L51: =L44*(L50-1) -> 0.0080697504 | ... O51: =O44*(O50-1) -> 0.00050892695
B52: AFtot = Total attributable fraction from noise exposure | C52: =C51/(1+C51) -> 0.027612335 | D52: =D51/(1+D51) -> 0.035037182
B53: YLD = YLD of the disease (= 0,0115708) * AFtot | C53: =0.0115708*C52 -> 0.00031949681 | D53: =0.0115708*D52 -> 0.00040540822
A54: Diabetes | B54: RR[Ni] = relative risk for each noise exposure category | E54: =IF(E43>$I$34, EXP((LN(1.062)/10)*(E43-$I$34)),1) -> 1 | F54: =IF(F43>$I$34, EXP((LN(1.062)/10)*(F43-$I$34)),1) -> 1 | G54: =IF(G43>$I$34, EXP((LN(1.062)/10)*(G43-$I$34)),1) -> 1 | H54: =IF(H43>$I$34, EXP((LN(1.062)/10)*(H43-$I$34)),1) -> 1 | I54: =IF(I43>$I$34, EXP((LN(1.062)/10)*(I43-$I$34)),1) -> 1.0121034 | J54: =IF(J43>$I$34, EXP((LN(1.062)/10)*(J43-$I$34)),1) -> 1.0430069 | K54: =IF(K43>$I$34, EXP((LN(1.062)/10)*(K43-$I$34)),1) -> 1.0748539 | L54: =IF(L43>$I$34, EXP((LN(1.062)/10)*(L43-$I$34)),1) -> 1.1076733 | ... O54: =IF(O43>$I$34, EXP((LN(1.062)/10)*(O43-$I$34)),1) -> 1.2122675
...

Sheet Fragen
A1: # | B1: Bezug | C1: Frage
A2: 1 | B2: p[i] = proportion of the population in each noise exposure category Ni | C2: Korrekt berechnet?
A3: 2 | B3: ERF[Ni] = product of the ERF of the all noise exposure categories | C3: bei HA und HSD: auch für midpoint of noise exposure in each category? "/100" für AR?
A4: 3 | B4: number of observed cases (Co) in each country | C4: Bevölkerung über 18? "Co represents the total target population size"
A5: 4 | B5: HA/ HSD | C5: Threshold?

Sheet ERF HRA

Sheet 5dB to 1dB refinement
A2: Methodology to improve the transfer process from 5 dB to 1 dB exposure distribution

Sheet Agglomeration rail
A1: Mean relative fractions from population above 55 dB L_den or above 50 dB L_night to estimate the population in lower 5 dB exposure categories for railway noise inside agglomerations
A2: Indicator | B2: Fraction 25 - 29 dB | C2: Fraction 30 - 34 dB | D2: Fraction 35 - 39 dB | E2: Fraction 40 - 44 dB | F2: Fraction 45 - 49 dB | G2: Fraction 50 - 54 dB
A3: L_den | B3: - | C3: - | D3: 1.68894 | E3: 1.05637 | F3: 0.68267 | G3: 0.71071
A4: L_night | B4: 2.88929 | C4: 1.80714 | D4: 1.16786 | E4: 0.71071 | F4: 0.77215 | G4: -
A6: Summe Belasteter nach END
A7: L_den >= 55 dB | B7: 100
A8: L_night >= 50 dB | B8: 100
A10: Imputation
A11: Indicator | B11: Belastete 25 - 29 dB | C11: Belastete 30 - 34 dB | D11: Belastete 35 - 39 dB | E11: Belastete 40 - 44 dB | F11: Belastete 45 - 49 dB | G11: Belastete 50 - 54 dB
A12: L_den | B12: - | C12: - | D12: =D3*(B7+G12+F12+E12) -> 999.74865 | E12: =E3*(B7+G12+F12) -> 304.08248 | F12: =F3*(B7+G12) -> 116.78504 | G12: =G3*B7 -> 71.071
A13: L_night | B13: =B4*(B8+F13+E13+D13+C13) -> 5330.4431 | C13: =C4*(B8+F13+E13+D13) -> 1187.6813 | D13: =D4*(B8+F13+E13) -> 354.05249 | E13: =E4*(B8+F13) -> 125.94847 | F13: =F4*B8 -> 77.215 | G13: -

Sheet Agglomeration air

Sheet Agglomeration industry

Sheet Major roads 

Sheet Major railways 

Sheet Major airports
